Error in rule create_database:
    jobid: 0
    output: output/db_name.txt

RuleException:
ProgrammingError in line 15 of /home/ddhoogduin/programs/KeyGenes-dataprocessor-v0.2/Snakefile:
(pymysql.err.ProgrammingError) (1064, "You have an error in your SQL syntax; check the manual that corresponds to your MySQL server version for the right syntax to use near '-db-xhfpl' at line 1")
[SQL: CREATE DATABASE KeyGenes-db-xhfpl]
(Background on this error at: http://sqlalche.me/e/f405)
  File "/home/ddhoogduin/programs/KeyGenes-dataprocessor-v0.2/Snakefile", line 15, in __rule_create_database
  File "/home/ddhoogduin/programs/KeyGenes-dataprocessor-v0.2/Database.py", line 49, in add_db
  File "/home/ddhoogduin/.local/lib/python3.6/site-packages/sqlalchemy/engine/base.py", line 976, in execute
  File "/home/ddhoogduin/.local/lib/python3.6/site-packages/sqlalchemy/engine/base.py", line 1151, in _execute_text
  File "/home/ddhoogduin/.local/lib/python3.6/site-packages/sqlalchemy/engine/base.py", line 1288, in _execute_context
  File "/home/ddhoogduin/.local/lib/python3.6/site-packages/sqlalchemy/engine/base.py", line 1482, in _handle_dbapi_exception
  File "/home/ddhoogduin/.local/lib/python3.6/site-packages/sqlalchemy/util/compat.py", line 178, in raise_
  File "/home/ddhoogduin/.local/lib/python3.6/site-packages/sqlalchemy/engine/base.py", line 1248, in _execute_context
  File "/home/ddhoogduin/.local/lib/python3.6/site-packages/sqlalchemy/engine/default.py", line 590, in do_execute
  File "/home/ddhoogduin/.local/lib/python3.6/site-packages/pymysql/cursors.py", line 170, in execute
  File "/home/ddhoogduin/.local/lib/python3.6/site-packages/pymysql/cursors.py", line 328, in _query
  File "/home/ddhoogduin/.local/lib/python3.6/site-packages/pymysql/connections.py", line 517, in query
  File "/home/ddhoogduin/.local/lib/python3.6/site-packages/pymysql/connections.py", line 732, in _read_query_result
  File "/home/ddhoogduin/.local/lib/python3.6/site-packages/pymysql/connections.py", line 1075, in read
  File "/home/ddhoogduin/.local/lib/python3.6/site-packages/pymysql/connections.py", line 684, in _read_packet
  File "/home/ddhoogduin/.local/lib/python3.6/site-packages/pymysql/protocol.py", line 220, in check_error
  File "/home/ddhoogduin/.local/lib/python3.6/site-packages/pymysql/err.py", line 109, in raise_mysql_exception
  File "/usr/lib/python3.6/concurrent/futures/thread.py", line 56, in run
Exiting because a job execution failed. Look above for error message
